Workbook

Sheet 说明
A1: 非标设计
A3: 非标直线传动选型（伺服 / 步进 / 丝杠 / 齿轮齿条）。与托辊铝座无关。只改「输入」黄格。
A4: 1. 只改「输入」黄色格子和下拉。
A5: 2. 安装方向可选：水平、垂直向上、垂直向下、倾斜上坡、倾斜下坡。倾斜必须填倾角。
A6: 3. 工件质量和机构质量分开填。不要用估计的 640 kg 当架子重。
A7: 4. 看「推荐」：结果右边就是公式和代入数字。完整 22 步在「计算过程」。采购没有该型号时，在输入页手选，到「对照」看安全系数。
A8: 5. 丝杠和齿轮齿条用同一推力对比。齿条请填减速比（默认 10）；直连=1 时力矩大，推荐常为无满足项。BK/BF 只属于丝杠。
A9: 6. 会审页是工艺、机械、计算机三句意见，随计算结果变。
A10: 7. 用 Excel 或 WPS 打开。若公式显示为文字，检查单元格格式为「常规」并允许计算。
A11: 8. 目录里 3210/3220 标现货=0，自动推荐不会选它们，手选仍可选（常无货）。
A12: 公式：F = mg·sinθ + μmg·cosθ + ma + F外；丝杠 T=F·P/(2πη)，n=v×1000/P；齿条齿轮 n0=v×1000/(π m z)，电机 n=n0×i，T=F·(mz/2000)/η/i/η减。

Sheet 输入
A1: 非标设计 伺服 / 步进 / 丝杠 / 齿轮齿条选型
A2: 黄格可改。改完先看「推荐」：结果旁边就是公式和代入数字。完整 22 步在「计算过程」。架子重量填实重，不要用别人估的 640 kg。
A3: 项目 | B3: 数值 | C3: 说明
A4: 安装方向 | B4: 水平 | C4: 水平 / 垂直向上 / 垂直向下 / 倾斜上坡 / 倾斜下坡
A5: 倾角_度 | B5: 0 | C5: 仅倾斜时填写，水平垂直填 0
A6: 工件质量_kg | B6: 151 | C6: 例如 3 根 Φ219 管约 151
A7: 机构质量_kg | B7: 200 | C7: 架子+滑座，按你的设计填
A8: 额外阻力_N | B8: 0 | C8: 刮屑、密封等，没有填 0
A9: 速度_m_min | B9: 8 | C9: 任务书上限 15，上料常用 6～8
A10: 行程_mm | B10: 2500 | C10: 影响丝杠会不会垂
A11: 加速时间_s | B11: 0.4 | C11: 越小加速力越大
A12: 摩擦系数 | B12: 0.1 | C12: 铜套约 0.1，直线导轨约 0.02
A13: 目标安全系数 | B13: 2 | C13: 运行力矩相对需要力矩
A14: 传动计算 | B14: 两种都算 | C14: 自动 / 只要丝杠 / 只要齿条 / 两种都算
A15: 丝杠效率 | B15: 0.9 | C15: 滚珠丝杠常用 0.90
A16: 齿条型式 | B16: 斜齿 | C16: 斜齿或直齿
A17: 齿条效率 | B17: 0.94 | C17: 斜齿 0.94，直齿改 0.90
A18: 齿条模数 | B18: 2 | C18: 给定清单：1.5 / 2 / 2.5 / 3
A19: 齿条齿数 | B19: 25 | C19: 给定清单：20 / 25 / 30
A20: 齿条减速比 | B20: 10 | C20: 1=直连（力矩大，目录常无满足项）。常用 8～15
A21: 减速机效率 | B21: 0.94 | C21: 直连（减速比=1）时公式按 1 计；行星常用 0.94
A23: 手选（可改下拉；选「用推荐」则跟推荐走）
A24: 手选丝杠 | B24: （用推荐）
A25: 手选伺服 | B25: （用推荐）
A26: 手选步进 | B26: （用推荐）
A27: 手选齿条模数 | B27: （用推荐）
A28: 手选齿条齿数 | B28: （用推荐）
A29: 手选齿条减速比 | B29: （用推荐）

Sheet 推荐
A1: 非标设计 推荐结果（只读；右边是公式和代入）
A2: =输入!B4&" 总质量 "&TEXT(计算!B2,"0.00")&" kg 速度 "&TEXT(输入!B9,"0.00")&" m/min 工作推力 "&TEXT(计算!B6,"0.0")&" N。完整 22 步见「计算过程」。
A3: 项目 | B3: 结果 | C3: 公式 | D3: 代入（数字随输入变）
A4: 总质量 kg | B4: =计算!B2 | C4: m = 工件 + 机构 | D4: =TEXT(输入!B6,"0.00")&" + "&TEXT(输入!B7,"0.00")&" = "&TEXT(计算!B2,"0.00")&" kg"
A5: 速度 m/s | B5: =计算!B3 | C5: v = 速度(m/min) ÷ 60 | D5: =TEXT(输入!B9,"0.00")&" / 60 = "&TEXT(计算!B3,"0.000")&" m/s"
A6: 加速度 m/s² | B6: =计算!B4 | C6: a = v ÷ 加速时间 | D6: =TEXT(计算!B3,"0.000")&" / "&TEXT(输入!B11,"0.00")&" = "&TEXT(计算!B4,"0.000")&" m/s²"
A7: 等效倾角 ° | B7: =计算!B5 | C7: 水平0；垂直上+90；垂直下−90；倾斜取填角（下坡为负） | D7: =输入!B4&" → "&TEXT(计算!B5,"0.0")&" ° sin="&TEXT(计算!B41,"0.000")&" cos="&TEXT(计算!B42,"0.000")
A8: 沿程重力 N | B8: =计算!B7 | C8: Fg = m g sinθ | D8: =TEXT(计算!B2,"0.00")&" × 9.81 × SIN("&TEXT(计算!B5,"0.0")&"°) = "&TEXT(计算!B7,"0.0")&" N"
A9: 摩擦力 N | B9: =计算!B8 | C9: Ff = μ m g |cosθ| | D9: =TEXT(输入!B12,"0.00")&" × "&TEXT(计算!B2,"0.00")&" × 9.81 × |"&TEXT(计算!B42,"0.000")&"| = "&TEXT(计算!B8,"0.0")&" N"
A10: 加速力 N | B10: =计算!B9 | C10: Fa = m a | D10: =TEXT(计算!B2,"0.00")&" × "&TEXT(计算!B4,"0.000")&" = "&TEXT(计算!B9,"0.0")&" N"
A11: 工作推力 N | B11: =计算!B6 | C11: F = |Fg + Ff + Fa + F外| | D11: ="("&TEXT(计算!B7,"0.0")&") + ("&TEXT(计算!B8,"0.0")&") + ("&TEXT(计算!B9,"0.0")&") + ("&TEXT(输入!B8,"0.0")&") = "&TEXT(计算!B45,"0.0")&" → |F|="&TEXT(计算!B6,"0.0")&" N"
A12: 是否倒拖 | B12: =计算!B10 | C12: 重力沿走向与运动相反时为倒拖 | D12: =计算!B10&IF(计算!B10="是"," 必须抱闸"," 水平一般不倒拖，仍建议刹车")
A13: ↓ 丝杠方案
A14: 推荐丝杠 | B14: =计算!B12 | C14: 目录第一档现货且转速、临界、轴径都过的 | D14: =计算!B12&" 直径 "&TEXT(INDEX(目录丝杠!B2:B13,计算!B11),"0")&" 导程 "&TEXT(计算!B40,"0")&" mm"
A15: 丝杠转速 r/min | B15: =计算!B13 | C15: n = v(m/min)×1000 / 导程(mm) | D15: =TEXT(输入!B9,"0.00")&" × 1000 / "&TEXT(计算!B40,"0")&" = "&TEXT(计算!B13,"0.0")&" r/min"
A16: 丝杠转矩 N·m | B16: =计算!B14 | C16: T = F × P / (2π η)，P 为导程(m) 即 导程mm/1000 | D16: ="F="&TEXT(计算!B6,"0.0")&"，P="&TEXT(计算!B40,"0")&" mm，η="&TEXT(输入!B15,"0.00")&"，2πη="&TEXT(计算!B43,"0.000")&" → T="&TEXT(计算!B14,"0.000")&" N·m"
A17: 丝杠机械功率 kW | B17: =计算!B36 | C17: P = T n / 9550 | D17: =TEXT(计算!B14,"0.000")&" × "&TEXT(计算!B13,"0.0")&" / 9550 = "&TEXT(计算!B36,"0.000")&" kW"
A18: 轴承座 | B18: =计算!B16&" + "&计算!B17 | C18: 按丝杠直径配 BK 固定 + BF 游动 | D18: =计算!B16&" + "&计算!B17&"；BK内 "&计算!B18&"；BF内 "&计算!B19
A19: 推荐伺服（丝杠） | B19: =计算!B30 | C19: 目录中运行 SF≥目标 且 启动 SF≥1.5 的最小一档 | D19: =计算!B30&" 目标SF="&TEXT(输入!B13,"0.00")
A20: 推荐步进（丝杠） | B20: =计算!B31 | C20: 按该转速掉矩后仍满足安全系数 | D20: =计算!B31
A21: ↓ 齿条方案
A22: 推荐齿条 | B22: =TEXT(输入!B18,"0.0")&"模 × "&TEXT(输入!B19,"0")&"齿 "&输入!B16&" i="&TEXT(输入!B20,"0") | C22: 模数、齿数、减速比来自输入页 | D22: ="节圆半径 r="&TEXT(计算!B44,"0.0")&" mm（= m z / 2）"
A23: 齿轮轴转速 r/min | B23: =计算!B39 | C23: n0 = v×1000 / (π m z) | D23: =TEXT(输入!B9,"0.00")&"×1000 / (π×"&TEXT(输入!B18,"0.0")&"×"&TEXT(输入!B19,"0")&") = "&TEXT(计算!B39,"0.00")&" r/min"
A24: 齿条电机转速 r/min | B24: =计算!B20 | C24: n电机 = n0 × i | D24: =TEXT(计算!B39,"0.00")&" × "&TEXT(输入!B20,"0")&" = "&TEXT(计算!B20,"0.00")&" r/min"
A25: 齿条电机转矩 N·m | B25: =计算!B21 | C25: T电机 = F×(m z /2000) / η齿 / i / η减 | D25: ="F="&TEXT(计算!B6,"0.0")&"，mz/2000="&TEXT(输入!B18*输入!B19/2000,"0.000")&"，η齿="&TEXT(输入!B17,"0.00")&"，i="&TEXT(输入!B20,"0")&"，η减="&TEXT(IF(输入!B20<=1,1,输入!B21),"0.00")&" → T="&TEXT(计算!B21,"0.000")&" N·m"
A26: 齿条机械功率 kW | B26: =计算!B37 | C26: P = T电机 n电机 / 9550 | D26: =TEXT(计算!B21,"0.000")&" × "&TEXT(计算!B20,"0.0")&" / 9550 = "&TEXT(计算!B37,"0.000")&" kW"
A27: 推荐伺服（齿条） | B27: =计算!B32 | C27: 按减速后的 n、T 再选 | D27: =计算!B32
A28: 推荐步进（齿条） | B28: =计算!B33 | C28: 按减速后的 n、T 再选 | D28: =计算!B33
A30: 传动选「只要丝杠」时，齿条几行仍会算，只是不当采购依据。手选型号到「对照」看安全系数。改输入后本页数字一起变。

Sheet 计算过程
A1: 非标设计 计算过程（随输入自动变，只读）
A2: 先看本页步骤，再看「推荐」「对照」。公式与「计算」页同一套。
A4: 步骤 | B4: 公式 | C4: 代入与结果 | D4: 说明
A5: 1 总质量 | B5: m = 工件 + 机构 | C5: =TEXT(输入!B6,"0.00")&" + "&TEXT(输入!B7,"0.00")&" = "&TEXT(计算!B2,"0.00")&" kg" | D5: 架子请填实重，不要用估计的 640 kg
A6: 2 速度 | B6: v = 速度(m/min) ÷ 60 | C6: =TEXT(输入!B9,"0.00")&" / 60 = "&TEXT(计算!B3,"0.000")&" m/s" | D6: 后面加速度、功率都用 m/s
A7: 3 加速度 | B7: a = v ÷ 加速时间 | C7: =TEXT(计算!B3,"0.000")&" / "&TEXT(输入!B11,"0.00")&" = "&TEXT(计算!B4,"0.000")&" m/s²" | D7: 时间越短，加速力越大
A8: 4 等效倾角 | B8: 水平0°；垂直上+90°；垂直下−90°；倾斜取填角（下坡为负） | C8: =输入!B4&" → "&TEXT(计算!B5,"0.0")&" °" | D8: 倾斜必须在输入页填倾角
A9: 5 沿程重力 | B9: Fg = m g sinθ | C9: =TEXT(计算!B2,"0.00")&" × 9.81 × SIN("&TEXT(计算!B5,"0.0")&"°) = "&TEXT(计算!B2,"0.00")&" × 9.81 × "&TEXT(计算!B41,"0.000")&" = "&TEXT(计算!B7,"0.0")&" N" | D9: 水平上坡为正、下坡为负
A10: 6 摩擦力 | B10: Ff = μ m g |cosθ| | C10: =TEXT(输入!B12,"0.00")&" × "&TEXT(计算!B2,"0.00")&" × 9.81 × |"&TEXT(计算!B42,"0.000")&"| = "&TEXT(计算!B8,"0.0")&" N" | D10: 铜套 μ≈0.1，导轨 μ≈0.02
A11: 7 加速力 | B11: Fa = m a | C11: =TEXT(计算!B2,"0.00")&" × "&TEXT(计算!B4,"0.000")&" = "&TEXT(计算!B9,"0.0")&" N"
A12: 8 工作推力 | B12: F = |Fg + Ff + Fa + F外| | C12: ="("&TEXT(计算!B7,"0.0")&") + ("&TEXT(计算!B8,"0.0")&") + ("&TEXT(计算!B9,"0.0")&") + ("&TEXT(输入!B8,"0.0")&") = "&TEXT(计算!B45,"0.0")&" → |F|="&TEXT(计算!B6,"0.0")&" N" | D12: 电机按这个 F 来算转矩
A13: 9 是否倒拖 | B13: 重力沿走向与运动相反时为倒拖 | C13: =计算!B10 | D13: 倒拖必须抱闸
A14: 10 丝杠型号 | B14: 目录中第一档「可用」现货 | C14: =计算!B12 | D14: 优先 2510 / 4010
A15: 11 丝杠转速 | B15: n = v(m/min)×1000 / 导程(mm) | C15: =TEXT(输入!B9,"0.00")&" × 1000 / "&TEXT(计算!B40,"0")&" = "&TEXT(计算!B13,"0.0")&" r/min" | D15: 导程 10 时，8 m/min → 800 r/min
A16: 12 丝杠转矩 | B16: T = F × P / (2π η)，P 为导程(m)=导程mm/1000 | C16: ="F="&TEXT(计算!B6,"0.0")&"，P="&TEXT(计算!B40,"0")&" mm，η="&TEXT(输入!B15,"0.00")&"，2πη="&TEXT(计算!B43,"0.000")&" → T="&TEXT(计算!B6,"0.0")&"×"&TEXT(计算!B40,"0")&"/1000/"&TEXT(计算!B43,"0.000")&" = "&TEXT(计算!B14,"0.000")&" N·m" | D16: 效率默认 0.90
A17: 13 丝杠功率 | B17: P = T n / 9550 | C17: =TEXT(计算!B14,"0.000")&" × "&TEXT(计算!B13,"0.0")&" / 9550 = "&TEXT(计算!B36,"0.000")&" kW" | D17: 这是机械功率，电机按目录再留安全系数
A18: 14 轴承座 | B18: 按丝杠直径配 BK 固定 + BF 游动 | C18: =计算!B16&" + "&计算!B17&"；BK内 "&计算!B18&"；BF内 "&计算!B19 | D18: BK 是一对角接触，BF 是一只深沟球
A19: 15 齿轮轴转速 | B19: n0 = v×1000 / (π m z) | C19: =TEXT(输入!B9,"0.00")&"×1000 / (π×"&TEXT(输入!B18,"0.0")&"×"&TEXT(输入!B19,"0")&") = "&TEXT(计算!B39,"0.00")&" r/min" | D19: 减速前，齿轮转得慢
A20: 16 齿条电机转速 | B20: n电机 = n0 × i | C20: =TEXT(计算!B39,"0.00")&" × "&TEXT(输入!B20,"0")&" = "&TEXT(计算!B20,"0.00")&" r/min" | D20: i=1 为直连；默认 i=10
A21: 17 齿条电机转矩 | B21: T电机 = F×(m z /2000) / η齿 / i / η减 | C21: ="F="&TEXT(计算!B6,"0.0")&" × "&TEXT(输入!B18*输入!B19/2000,"0.000")&" / "&TEXT(输入!B17,"0.00")&" / "&TEXT(输入!B20,"0")&" / "&TEXT(IF(输入!B20<=1,1,输入!B21),"0.00")&" = "&TEXT(计算!B21,"0.000")&" N·m" | D21: 直连 i=1 时 T 很大，目录会无满足项
A22: 18 齿条功率 | B22: P = T电机 n电机 / 9550 | C22: =TEXT(计算!B21,"0.000")&" × "&TEXT(计算!B20,"0.0")&" / 9550 = "&TEXT(计算!B37,"0.000")&" kW" | D22: 与丝杠功率应接近（差在效率）
A23: 19 丝杠用伺服 | B23: 目录中运行 SF≥目标 且 启动 SF≥1.5 的最小一档 | C23: =计算!B30 | D23: 目标安全系数见输入页
A24: 20 丝杠用步进 | B24: 按该转速掉矩后仍满足安全系数 | C24: =计算!B31 | D24: 转速高时 86 可能不够，改 110
A25: 21 齿条用伺服 | B25: 按减速后的 n、T 再选 | C25: =计算!B32 | D25: 仍无满足项就加大 i
A26: 22 齿条用步进 | B26: 同上 | C26: =计算!B33

Sheet 对照
A1: 非标设计 丝杠方案 vs 齿轮齿条方案（同一载荷、同一速度）
A3: 项目 | B3: 滚珠丝杠 | C3: 齿轮齿条
A4: 效率 | B4: =输入!B15 | C4: =输入!B17*IF(输入!B20<=1,1,输入!B21)
A5: 减速比 | B5: 1（丝杠直连） | C5: =输入!B20
A6: 电机转速 r/min | B6: =计算!B13 | C6: =计算!B20
A7: 需要转矩 N·m | B7: =计算!B14 | C7: =计算!B21
A8: 机械功率 kW | B8: =计算!B36 | C8: =计算!B37
A9: 推荐伺服 | B9: =计算!B30 | C9: =计算!B32
A10: 推荐步进 | B10: =计算!B31 | C10: =计算!B33
A11: 支承 | B11: =计算!B16&" + "&计算!B17 | C11: 减速机+齿轮轴轴承（不是BK座）
A12: 行程适应性 | B12: =IF(输入!B10>4000,"长行程丝杠易垂","短中行程合适") | C12: =IF(输入!B10>4000,"长行程更合适","短行程也能用")
A13: 效率谁高 | C13: =IF(输入!B17*IF(输入!B20<=1,1,输入!B21)>输入!B15,"齿条链效率更高","丝杠效率更高或相当")
A15: 手选后（与推荐可能不同）
A16: 项目 | B16: 手选丝杠方案 | C16: 手选齿条方案
A17: 型号/参数 | B17: =计算!B27 | C17: =TEXT(计算!B23,"0.0")&"×"&TEXT(计算!B24,"0")&" "&输入!B16&" i="&TEXT(计算!B38,"0")
A18: 转速 | B18: =计算!B28 | C18: =计算!B25
A19: 转矩 | B19: =计算!B29 | C19: =计算!B26
A20: 伺服 | B20: =计算!B34 | C20: =计算!B34
A21: 步进 | B21: =计算!B35 | C21: =计算!B35
A23: 手选电机的安全系数见「目录电机」里对应行的运行SF；低于目标安全系数不要当正式方案。齿条直连（减速比=1）力矩很大，目录可能仍无满足项，请把减速比改为 8～15。

Sheet 会审
A1: 非标设计 工艺 / 机械 / 计算机会审
A3: 机械工程师
A4: =CONCATENATE("工作推力 ",TEXT(计算!B6,"0")," N，总质量 ",TEXT(计算!B2,"0.0")," kg。丝杠推荐 ",计算!B12,"，座 ",计算!B16,"+",计算!B17,"。齿条模数",TEXT(输入!B18,"0.0")," 齿数",TEXT(输入!B19,"0")," 减速比 i=",TEXT(输入!B20,"0"),"。BK只配丝杠，不要装到齿条上。")
A5: =IF(计算!B10="是","垂直或下坡有倒拖，必须抱闸，BF端不要锁死。","水平无倒拖，仍建议电机带刹车，停电不溜。")
A6: =IF(输入!B10>4000,"行程超过4米，机械建议优先齿条，丝杠要中间托。","行程不长，丝杠齿条都能做，对位要求高用丝杠。")
A8: 工艺工程师
A9: =IF(AND(输入!B9>=15,计算!B13>1200),"满速15 m/min且丝杠转速高：86步进当常用速度不稳，试车按点动再提速。","按当前速度可以试车：先对导向，再上传动，禁止硬掰同轴。")
A10: 成套买轴承座，不要拆了用两套深沟球顶替角接触。垂直、倾斜先确认停电刹车能抱住。
A11: =IF(输入!B7<50,"机构质量填得过小，核对架子实重再下单。","架子质量已手填，按实重校核有效。")
A13: 计算机工程师
A14: 只改「输入」黄格和下拉。计算、目录、推荐不要手改公式。导出或另存时文件名带日期。
A15: =CONCATENATE("建议文件名：选型_",输入!B4,"_",TEXT(输入!B9,"0"),"mmin_",计算!B12)
A16: 本表是唯一公式源。不要再做另一套网页算法。CAD 源文件不放进这张表。

Sheet 计算
A1: 符号 | B1: 数值
A2: 总质量kg | B2: =输入!B6+输入!B7
A3: 速度m_s | B3: =输入!B9/60
A4: 加速度 | B4: =B3/MAX(输入!B11,0.05)
A5: 等效倾角度 | B5: =IF(输入!B4="水平",0,IF(输入!B4="垂直向上",90,IF(输入!B4="垂直向下",-90,IF(输入!B4="倾斜上坡",输入!B5,-输入!B5))))
A6: 工作推力N | B6: =ABS(B2*9.81*SIN(B5*PI()/180)+输入!B12*B2*9.81*COS(B5*PI()/180)+B2*B4+输入!B8)
A7: 沿程重力N | B7: =B2*9.81*SIN(B5*PI()/180)
A8: 摩擦N | B8: =输入!B12*B2*9.81*ABS(COS(B5*PI()/180))
A9: 加速力N | B9: =B2*B4
A10: 是否倒拖 | B10: =IF(B2*9.81*SIN(B5*PI()/180)+B2*B4+输入!B8<0,"是","否")
A11: 推荐丝杠行 | B11: =IFERROR(MATCH(1,目录丝杠!J2:J13,0),1)
A12: 推荐丝杠 | B12: =INDEX(目录丝杠!A2:A13,B11)
A13: 丝杠转速 | B13: =INDEX(目录丝杠!F2:F13,B11)
A14: 丝杠工作转矩 | B14: =INDEX(目录丝杠!G2:G13,B11)
A15: 丝杠启动转矩 | B15: =B6*INDEX(目录丝杠!C2:C13,B11)/1000/(2*PI()*输入!B15)*IF(输入!B4="水平",MAX(输入!B12,0.15)/MAX(输入!B12,0.01),1)
A16: 推荐BK | B16: =INDEX(目录丝杠!K2:K13,B11)
A17: 推荐BF | B17: =INDEX(目录丝杠!L2:L13,B11)
A18: 角接触 | B18: =INDEX(目录丝杠!M2:M13,B11)
A19: 深沟球 | B19: =INDEX(目录丝杠!N2:N13,B11)
A20: 齿条电机转速 | B20: =输入!B9*1000/(PI()*输入!B18*输入!B19)*MAX(输入!B20,1)
A21: 齿条电机转矩 | B21: =B6*(输入!B18*输入!B19)/2000/输入!B17/MAX(输入!B20,1)/IF(输入!B20<=1,1,输入!B21)
A22: 齿条启动转矩 | B22: =B15/MAX(B14,0.01)*B21
A23: 有效齿条模数 | B23: =IF(输入!B27="（用推荐）",输入!B18,VALUE(输入!B27))
A24: 有效齿条齿数 | B24: =IF(输入!B28="（用推荐）",输入!B19,VALUE(输入!B28))
A25: 手选后齿条转速 | B25: =输入!B9*1000/(PI()*B23*B24)*MAX(B38,1)
A26: 手选后齿条转矩 | B26: =B6*(B23*B24)/2000/输入!B17/MAX(B38,1)/IF(B38<=1,1,输入!B21)
A27: 有效丝杠 | B27: =IF(输入!B24="（用推荐）",B12,输入!B24)
A28: 有效丝杠转速 | B28: =IFERROR(INDEX(目录丝杠!F2:F13,MATCH(B27,目录丝杠!A2:A13,0)),B13)
A29: 有效丝杠转矩 | B29: =IFERROR(INDEX(目录丝杠!G2:G13,MATCH(B27,目录丝杠!A2:A13,0)),B14)
A30: 推荐伺服 | B30: =IFERROR(INDEX(目录电机!B2:B7,MATCH(1,目录电机!K2:K7,0)),"无满足项，请降速或加大电机")
A31: 推荐步进 | B31: =IFERROR(INDEX(目录电机!B8:B12,MATCH(1,目录电机!K8:K12,0)),"无满足项，请降速或改110/130")
A32: 齿条推荐伺服 | B32: =IFERROR(INDEX(目录电机!B2:B7,MATCH(1,目录电机!O2:O7,0)),"无满足项，请加大减速比")
A33: 齿条推荐步进 | B33: =IFERROR(INDEX(目录电机!B8:B12,MATCH(1,目录电机!O8:O12,0)),"无满足项，请加大减速比")
A34: 有效伺服 | B34: =IF(输入!B25="（用推荐）",B30,输入!B25)
A35: 有效步进 | B35: =IF(输入!B26="（用推荐）",B31,输入!B26)
A36: 机械功率kW | B36: =B14*B13/9550
A37: 齿条功率kW | B37: =B21*B20/9550
A38: 有效减速比 | B38: =IF(输入!B29="（用推荐）",输入!B20,VALUE(输入!B29))
A39: 齿轮轴转速 | B39: =输入!B9*1000/(PI()*输入!B18*输入!B19)
A40: 推荐导程mm | B40: =INDEX(目录丝杠!C2:C13,B11)
...

Sheet 目录丝杠
A1: 型号 | B1: 直径mm | C1: 导程mm | D1: 动载kN | E1: 现货 | F1: 转速 | G1: 转矩 | H1: 丝杠长 | I1: 临界转速 | J1: 可用 | K1: BK | L1: BF | M1: 座内角接触 | N1: 座内深沟球
A2: SFU2510-3 | B2: 25 | C2: 10 | D2: 17.8 | E2: 1 | F2: =输入!$B$9*1000/C2 | G2: =计算!$B$6*C2/1000/(2*PI()*输入!$B$15) | H2: =输入!$B$10+400 | I2: =15.1E8*B2/H2^2*0.8 | J2: =IF(AND(E2=1,F2<=3000,F2<I2,IF(输入!$B$10>1800,B2>=25,TRUE),IF(AND(C2=5,F2>1400),FALSE,TRUE),IF(计算!$B$6>800,B2>=25,TRUE)),1,0) | K2: =IF(B2<=16,"BK12",IF(B2<=20,"BK15",IF(B2<=32,"BK20",IF(B2<=40,"BK25","BK30")))) | L2: =IF(B2<=16,"BF12",IF(B2<=20,"BF15",IF(B2<=32,"BF20",IF(B2<=40,"BF25","BF30")))) | M2: 7004AC×2 | N2: 6004ZZ
A3: SFU4010-3 | B3: 40 | C3: 10 | D3: 37.4 | E3: 1 | F3: =输入!$B$9*1000/C3 | G3: =计算!$B$6*C3/1000/(2*PI()*输入!$B$15) | H3: =输入!$B$10+400 | I3: =15.1E8*B3/H3^2*0.8 | J3: =IF(AND(E3=1,F3<=3000,F3<I3,IF(输入!$B$10>1800,B3>=25,TRUE),IF(AND(C3=5,F3>1400),FALSE,TRUE),IF(计算!$B$6>800,B3>=25,TRUE)),1,0) | K3: =IF(B3<=16,"BK12",IF(B3<=20,"BK15",IF(B3<=32,"BK20",IF(B3<=40,"BK25","BK30")))) | L3: =IF(B3<=16,"BF12",IF(B3<=20,"BF15",IF(B3<=32,"BF20",IF(B3<=40,"BF25","BF30")))) | M3: 7205AC×2 | N3: 6005ZZ
A4: SFU2010-3 | B4: 20 | C4: 10 | D4: 11 | E4: 1 | F4: =输入!$B$9*1000/C4 | G4: =计算!$B$6*C4/1000/(2*PI()*输入!$B$15) | H4: =输入!$B$10+400 | I4: =15.1E8*B4/H4^2*0.8 | J4: =IF(AND(E4=1,F4<=3000,F4<I4,IF(输入!$B$10>1800,B4>=25,TRUE),IF(AND(C4=5,F4>1400),FALSE,TRUE),IF(计算!$B$6>800,B4>=25,TRUE)),1,0) | K4: =IF(B4<=16,"BK12",IF(B4<=20,"BK15",IF(B4<=32,"BK20",IF(B4<=40,"BK25","BK30")))) | L4: =IF(B4<=16,"BF12",IF(B4<=20,"BF15",IF(B4<=32,"BF20",IF(B4<=40,"BF25","BF30")))) | M4: 7002AC×2 | N4: 6002ZZ
A5: SFU2505-3 | B5: 25 | C5: 5 | D5: 17.8 | E5: 1 | F5: =输入!$B$9*1000/C5 | G5: =计算!$B$6*C5/1000/(2*PI()*输入!$B$15) | H5: =输入!$B$10+400 | I5: =15.1E8*B5/H5^2*0.8 | J5: =IF(AND(E5=1,F5<=3000,F5<I5,IF(输入!$B$10>1800,B5>=25,TRUE),IF(AND(C5=5,F5>1400),FALSE,TRUE),IF(计算!$B$6>800,B5>=25,TRUE)),1,0) | K5: =IF(B5<=16,"BK12",IF(B5<=20,"BK15",IF(B5<=32,"BK20",IF(B5<=40,"BK25","BK30")))) | L5: =IF(B5<=16,"BF12",IF(B5<=20,"BF15",IF(B5<=32,"BF20",IF(B5<=40,"BF25","BF30")))) | M5: 7004AC×2 | N5: 6004ZZ
A6: SFU4005-3 | B6: 40 | C6: 5 | D6: 37.4 | E6: 1 | F6: =输入!$B$9*1000/C6 | G6: =计算!$B$6*C6/1000/(2*PI()*输入!$B$15) | H6: =输入!$B$10+400 | I6: =15.1E8*B6/H6^2*0.8 | J6: =IF(AND(E6=1,F6<=3000,F6<I6,IF(输入!$B$10>1800,B6>=25,TRUE),IF(AND(C6=5,F6>1400),FALSE,TRUE),IF(计算!$B$6>800,B6>=25,TRUE)),1,0) | K6: =IF(B6<=16,"BK12",IF(B6<=20,"BK15",IF(B6<=32,"BK20",IF(B6<=40,"BK25","BK30")))) | L6: =IF(B6<=16,"BF12",IF(B6<=20,"BF15",IF(B6<=32,"BF20",IF(B6<=40,"BF25","BF30")))) | M6: 7205AC×2 | N6: 6005ZZ
A7: SFU2005-3 | B7: 20 | C7: 5 | D7: 11 | E7: 1 | F7: =输入!$B$9*1000/C7 | G7: =计算!$B$6*C7/1000/(2*PI()*输入!$B$15) | H7: =输入!$B$10+400 | I7: =15.1E8*B7/H7^2*0.8 | J7: =IF(AND(E7=1,F7<=3000,F7<I7,IF(输入!$B$10>1800,B7>=25,TRUE),IF(AND(C7=5,F7>1400),FALSE,TRUE),IF(计算!$B$6>800,B7>=25,TRUE)),1,0) | K7: =IF(B7<=16,"BK12",IF(B7<=20,"BK15",IF(B7<=32,"BK20",IF(B7<=40,"BK25","BK30")))) | L7: =IF(B7<=16,"BF12",IF(B7<=20,"BF15",IF(B7<=32,"BF20",IF(B7<=40,"BF25","BF30")))) | M7: 7002AC×2 | N7: 6002ZZ
A8: SFU5010-3 | B8: 50 | C8: 10 | D8: 54 | E8: 1 | F8: =输入!$B$9*1000/C8 | G8: =计算!$B$6*C8/1000/(2*PI()*输入!$B$15) | H8: =输入!$B$10+400 | I8: =15.1E8*B8/H8^2*0.8 | J8: =IF(AND(E8=1,F8<=3000,F8<I8,IF(输入!$B$10>1800,B8>=25,TRUE),IF(AND(C8=5,F8>1400),FALSE,TRUE),IF(计算!$B$6>800,B8>=25,TRUE)),1,0) | K8: =IF(B8<=16,"BK12",IF(B8<=20,"BK15",IF(B8<=32,"BK20",IF(B8<=40,"BK25","BK30")))) | L8: =IF(B8<=16,"BF12",IF(B8<=20,"BF15",IF(B8<=32,"BF20",IF(B8<=40,"BF25","BF30")))) | M8: 7206AC×2 | N8: 6006ZZ
A9: SFU3205-3 | B9: 32 | C9: 5 | D9: 27 | E9: 1 | F9: =输入!$B$9*1000/C9 | G9: =计算!$B$6*C9/1000/(2*PI()*输入!$B$15) | H9: =输入!$B$10+400 | I9: =15.1E8*B9/H9^2*0.8 | J9: =IF(AND(E9=1,F9<=3000,F9<I9,IF(输入!$B$10>1800,B9>=25,TRUE),IF(AND(C9=5,F9>1400),FALSE,TRUE),IF(计算!$B$6>800,B9>=25,TRUE)),1,0) | K9: =IF(B9<=16,"BK12",IF(B9<=20,"BK15",IF(B9<=32,"BK20",IF(B9<=40,"BK25","BK30")))) | L9: =IF(B9<=16,"BF12",IF(B9<=20,"BF15",IF(B9<=32,"BF20",IF(B9<=40,"BF25","BF30")))) | M9: 7004AC×2 | N9: 6004ZZ
A10: SFU1605-3 | B10: 16 | C10: 5 | D10: 7.8 | E10: 1 | F10: =输入!$B$9*1000/C10 | G10: =计算!$B$6*C10/1000/(2*PI()*输入!$B$15) | H10: =输入!$B$10+400 | I10: =15.1E8*B10/H10^2*0.8 | J10: =IF(AND(E10=1,F10<=3000,F10<I10,IF(输入!$B$10>1800,B10>=25,TRUE),IF(AND(C10=5,F10>1400),FALSE,TRUE),IF(计算!$B$6>800,B10>=25,TRUE)),1,0) | K10: =IF(B10<=16,"BK12",IF(B10<=20,"BK15",IF(B10<=32,"BK20",IF(B10<=40,"BK25","BK30")))) | L10: =IF(B10<=16,"BF12",IF(B10<=20,"BF15",IF(B10<=32,"BF20",IF(B10<=40,"BF25","BF30")))) | M10: 7001AC×2 | N10: 6001ZZ
A11: SFU3210-3 | B11: 32 | C11: 10 | D11: 27 | E11: 0 | F11: =输入!$B$9*1000/C11 | G11: =计算!$B$6*C11/1000/(2*PI()*输入!$B$15) | H11: =输入!$B$10+400 | I11: =15.1E8*B11/H11^2*0.8 | J11: =IF(AND(E11=1,F11<=3000,F11<I11,IF(输入!$B$10>1800,B11>=25,TRUE),IF(AND(C11=5,F11>1400),FALSE,TRUE),IF(计算!$B$6>800,B11>=25,TRUE)),1,0) | K11: =IF(B11<=16,"BK12",IF(B11<=20,"BK15",IF(B11<=32,"BK20",IF(B11<=40,"BK25","BK30")))) | L11: =IF(B11<=16,"BF12",IF(B11<=20,"BF15",IF(B11<=32,"BF20",IF(B11<=40,"BF25","BF30")))) | M11: 7004AC×2 | N11: 6004ZZ
A12: SFU3220-3 | B12: 32 | C12: 20 | D12: 27 | E12: 0 | F12: =输入!$B$9*1000/C12 | G12: =计算!$B$6*C12/1000/(2*PI()*输入!$B$15) | H12: =输入!$B$10+400 | I12: =15.1E8*B12/H12^2*0.8 | J12: =IF(AND(E12=1,F12<=3000,F12<I12,IF(输入!$B$10>1800,B12>=25,TRUE),IF(AND(C12=5,F12>1400),FALSE,TRUE),IF(计算!$B$6>800,B12>=25,TRUE)),1,0) | K12: =IF(B12<=16,"BK12",IF(B12<=20,"BK15",IF(B12<=32,"BK20",IF(B12<=40,"BK25","BK30")))) | L12: =IF(B12<=16,"BF12",IF(B12<=20,"BF15",IF(B12<=32,"BF20",IF(B12<=40,"BF25","BF30")))) | M12: 7004AC×2 | N12: 6004ZZ
A13: SFU4020-3 | B13: 40 | C13: 20 | D13: 37.4 | E13: 0 | F13: =输入!$B$9*1000/C13 | G13: =计算!$B$6*C13/1000/(2*PI()*输入!$B$15) | H13: =输入!$B$10+400 | I13: =15.1E8*B13/H13^2*0.8 | J13: =IF(AND(E13=1,F13<=3000,F13<I13,IF(输入!$B$10>1800,B13>=25,TRUE),IF(AND(C13=5,F13>1400),FALSE,TRUE),IF(计算!$B$6>800,B13>=25,TRUE)),1,0) | K13: =IF(B13<=16,"BK12",IF(B13<=20,"BK15",IF(B13<=32,"BK20",IF(B13<=40,"BK25","BK30")))) | L13: =IF(B13<=16,"BF12",IF(B13<=20,"BF15",IF(B13<=32,"BF20",IF(B13<=40,"BF25","BF30")))) | M13: 7205AC×2 | N13: 6005ZZ
A20: 手选下拉用
A21: （用推荐）
A22: SFU2510-3
A23: SFU4010-3
A24: SFU2010-3
A25: SFU2505-3
A26: SFU4005-3
A27: SFU2005-3
A28: SFU5010-3
A29: SFU3205-3
A30: SFU1605-3
A31: SFU3210-3
... A33: SFU4020-3

Sheet 目录电机
A1: 类型 | B1: 名称 | C1: 机座 | D1: 额定或静矩 | E1: 峰值或持矩 | F1: 额定转速 | G1: 功率档kW | H1: 丝杠方案可用矩 | I1: 丝杠运行SF | J1: 丝杠启动SF | K1: 丝杠可用 | L1: 齿条方案可用矩 | M1: 齿条运行SF | N1: 齿条启动SF | O1: 齿条可用
A2: 伺服 | B2: 0.4 kW 伺服带刹车 | C2: 60 | D2: 1.27 | E2: 3.81 | F2: 3000 | G2: 0.4 | H2: =IF(计算!$B$13<=F2,D2,D2*F2/MAX(计算!$B$13,1)) | I2: =H2/MAX(计算!$B$14,0.01) | J2: =E2/MAX(计算!$B$15,0.01) | K2: =IF(AND(I2>=输入!$B$13,J2>=1.5,计算!$B$13<=F2*1.05),1,0) | L2: =IF(计算!$B$20<=F2,D2,D2*F2/MAX(计算!$B$20,1)) | M2: =L2/MAX(计算!$B$21,0.01) | N2: =E2/MAX(计算!$B$22,0.01) | O2: =IF(AND(M2>=输入!$B$13,N2>=1.5,计算!$B$20<=F2*1.05),1,0)
A3: 伺服 | B3: 0.75 kW 伺服带刹车 | C3: 80 | D3: 2.39 | E3: 7.16 | F3: 3000 | G3: 0.75 | H3: =IF(计算!$B$13<=F3,D3,D3*F3/MAX(计算!$B$13,1)) | I3: =H3/MAX(计算!$B$14,0.01) | J3: =E3/MAX(计算!$B$15,0.01) | K3: =IF(AND(I3>=输入!$B$13,J3>=1.5,计算!$B$13<=F3*1.05),1,0) | L3: =IF(计算!$B$20<=F3,D3,D3*F3/MAX(计算!$B$20,1)) | M3: =L3/MAX(计算!$B$21,0.01) | N3: =E3/MAX(计算!$B$22,0.01) | O3: =IF(AND(M3>=输入!$B$13,N3>=1.5,计算!$B$20<=F3*1.05),1,0)
A4: 伺服 | B4: 1.0 kW 伺服带刹车 | C4: 80 | D4: 3.18 | E4: 9.54 | F4: 3000 | G4: 1 | H4: =IF(计算!$B$13<=F4,D4,D4*F4/MAX(计算!$B$13,1)) | I4: =H4/MAX(计算!$B$14,0.01) | J4: =E4/MAX(计算!$B$15,0.01) | K4: =IF(AND(I4>=输入!$B$13,J4>=1.5,计算!$B$13<=F4*1.05),1,0) | L4: =IF(计算!$B$20<=F4,D4,D4*F4/MAX(计算!$B$20,1)) | M4: =L4/MAX(计算!$B$21,0.01) | N4: =E4/MAX(计算!$B$22,0.01) | O4: =IF(AND(M4>=输入!$B$13,N4>=1.5,计算!$B$20<=F4*1.05),1,0)
A5: 伺服 | B5: 1.5 kW 伺服带刹车 | C5: 100 | D5: 4.77 | E5: 14.3 | F5: 3000 | G5: 1.5 | H5: =IF(计算!$B$13<=F5,D5,D5*F5/MAX(计算!$B$13,1)) | I5: =H5/MAX(计算!$B$14,0.01) | J5: =E5/MAX(计算!$B$15,0.01) | K5: =IF(AND(I5>=输入!$B$13,J5>=1.5,计算!$B$13<=F5*1.05),1,0) | L5: =IF(计算!$B$20<=F5,D5,D5*F5/MAX(计算!$B$20,1)) | M5: =L5/MAX(计算!$B$21,0.01) | N5: =E5/MAX(计算!$B$22,0.01) | O5: =IF(AND(M5>=输入!$B$13,N5>=1.5,计算!$B$20<=F5*1.05),1,0)
A6: 伺服 | B6: 2.0 kW 伺服带刹车 | C6: 100 | D6: 6.37 | E6: 19.1 | F6: 3000 | G6: 2 | H6: =IF(计算!$B$13<=F6,D6,D6*F6/MAX(计算!$B$13,1)) | I6: =H6/MAX(计算!$B$14,0.01) | J6: =E6/MAX(计算!$B$15,0.01) | K6: =IF(AND(I6>=输入!$B$13,J6>=1.5,计算!$B$13<=F6*1.05),1,0) | L6: =IF(计算!$B$20<=F6,D6,D6*F6/MAX(计算!$B$20,1)) | M6: =L6/MAX(计算!$B$21,0.01) | N6: =E6/MAX(计算!$B$22,0.01) | O6: =IF(AND(M6>=输入!$B$13,N6>=1.5,计算!$B$20<=F6*1.05),1,0)
A7: 伺服 | B7: 3.0 kW 伺服带刹车 | C7: 130 | D7: 9.55 | E7: 28.6 | F7: 3000 | G7: 3 | H7: =IF(计算!$B$13<=F7,D7,D7*F7/MAX(计算!$B$13,1)) | I7: =H7/MAX(计算!$B$14,0.01) | J7: =E7/MAX(计算!$B$15,0.01) | K7: =IF(AND(I7>=输入!$B$13,J7>=1.5,计算!$B$13<=F7*1.05),1,0) | L7: =IF(计算!$B$20<=F7,D7,D7*F7/MAX(计算!$B$20,1)) | M7: =L7/MAX(计算!$B$21,0.01) | N7: =E7/MAX(计算!$B$22,0.01) | O7: =IF(AND(M7>=输入!$B$13,N7>=1.5,计算!$B$20<=F7*1.05),1,0)
A8: 步进 | B8: 57 闭环带刹车 | C8: 57 | D8: 2.2 | E8: 2.2 | F8: 1500 | G8: 0.2 | H8: =D8/(1+(计算!$B$13/600)^1.6) | I8: =H8/MAX(计算!$B$14,0.01) | J8: =E8/MAX(计算!$B$15,0.01) | K8: =IF(AND(I8>=输入!$B$13,J8>=1.5,计算!$B$13<=F8*1.05),1,0) | L8: =D8/(1+(计算!$B$20/600)^1.6) | M8: =L8/MAX(计算!$B$21,0.01) | N8: =E8/MAX(计算!$B$22,0.01) | O8: =IF(AND(M8>=输入!$B$13,N8>=1.5,计算!$B$20<=F8*1.05),1,0)
A9: 步进 | B9: 86 闭环 8 N·m 带刹车 | C9: 86 | D9: 8 | E9: 8 | F9: 1500 | G9: 0.55 | H9: =D9/(1+(计算!$B$13/600)^1.6) | I9: =H9/MAX(计算!$B$14,0.01) | J9: =E9/MAX(计算!$B$15,0.01) | K9: =IF(AND(I9>=输入!$B$13,J9>=1.5,计算!$B$13<=F9*1.05),1,0) | L9: =D9/(1+(计算!$B$20/600)^1.6) | M9: =L9/MAX(计算!$B$21,0.01) | N9: =E9/MAX(计算!$B$22,0.01) | O9: =IF(AND(M9>=输入!$B$13,N9>=1.5,计算!$B$20<=F9*1.05),1,0)
A10: 步进 | B10: 86 闭环 12 N·m 带刹车 | C10: 86 | D10: 12 | E10: 12 | F10: 1500 | G10: 0.75 | H10: =D10/(1+(计算!$B$13/600)^1.6) | I10: =H10/MAX(计算!$B$14,0.01) | J10: =E10/MAX(计算!$B$15,0.01) | K10: =IF(AND(I10>=输入!$B$13,J10>=1.5,计算!$B$13<=F10*1.05),1,0) | L10: =D10/(1+(计算!$B$20/600)^1.6) | M10: =L10/MAX(计算!$B$21,0.01) | N10: =E10/MAX(计算!$B$22,0.01) | O10: =IF(AND(M10>=输入!$B$13,N10>=1.5,计算!$B$20<=F10*1.05),1,0)
A11: 步进 | B11: 110 闭环 20 N·m 带刹车 | C11: 110 | D11: 20 | E11: 20 | F11: 1500 | G11: 1.2 | H11: =D11/(1+(计算!$B$13/600)^1.6) | I11: =H11/MAX(计算!$B$14,0.01) | J11: =E11/MAX(计算!$B$15,0.01) | K11: =IF(AND(I11>=输入!$B$13,J11>=1.5,计算!$B$13<=F11*1.05),1,0) | L11: =D11/(1+(计算!$B$20/600)^1.6) | M11: =L11/MAX(计算!$B$21,0.01) | N11: =E11/MAX(计算!$B$22,0.01) | O11: =IF(AND(M11>=输入!$B$13,N11>=1.5,计算!$B$20<=F11*1.05),1,0)
A12: 步进 | B12: 130 闭环 25 N·m 带刹车 | C12: 130 | D12: 25 | E12: 25 | F12: 1500 | G12: 1.8 | H12: =D12/(1+(计算!$B$13/600)^1.6) | I12: =H12/MAX(计算!$B$14,0.01) | J12: =E12/MAX(计算!$B$15,0.01) | K12: =IF(AND(I12>=输入!$B$13,J12>=1.5,计算!$B$13<=F12*1.05),1,0) | L12: =D12/(1+(计算!$B$20/600)^1.6) | M12: =L12/MAX(计算!$B$21,0.01) | N12: =E12/MAX(计算!$B$22,0.01) | O12: =IF(AND(M12>=输入!$B$13,N12>=1.5,计算!$B$20<=F12*1.05),1,0)
A20: 伺服下拉 | B20: 步进下拉
A21: （用推荐） | B21: （用推荐）
A22: 0.4 kW 伺服带刹车 | B22: 57 闭环带刹车
A23: 0.75 kW 伺服带刹车 | B23: 86 闭环 8 N·m 带刹车
A24: 1.0 kW 伺服带刹车 | B24: 86 闭环 12 N·m 带刹车
A25: 1.5 kW 伺服带刹车 | B25: 110 闭环 20 N·m 带刹车
A26: 2.0 kW 伺服带刹车 | B26: 130 闭环 25 N·m 带刹车
A27: 3.0 kW 伺服带刹车
